Workbook

Sheet Report 1
A1: BÁO CÁO CÁC CÔNG VIỆC CHUNG PHÒNG BIM
A2: STT | B2: Công việc chính | C2: Tổng số đầu việc | D2: Số đầu việc đang thực hiện | E2: Số đầu việc hoàn thành | F2: Số đầu việc tạm dừng | G2: Số đầu việc quá hạn
A3: 1 | B3: Xây dựng HTTC BIM | C3: =SUM(D3:G3) -> 40 | D3: 10 | E3: 10 | F3: 10 | G3: 10
A4: 2 | B4: Đào tạo BIM | C4: =SUM(D4:G4) -> 44 | D4: 11 | E4: 11 | F4: 11 | G4: 11
A5: 3 | B5: Quản lý BIM | C5: =SUM(D5:G5) -> 48 | D5: 12 | E5: 12 | F5: 12 | G5: 12
A6: 4 | B6: Thanh tra BIM | C6: =SUM(D6:G6) -> 52 | D6: 13 | E6: 13 | F6: 13 | G6: 13
A7: 5 | B7: Phát triển BIM Tools | C7: =SUM(D7:G7) -> 56 | D7: 14 | E7: 14 | F7: 14 | G7: 14
A8: 6 | B8: Quản lý phần mềm | C8: =SUM(D8:G8) -> 60 | D8: 15 | E8: 15 | F8: 15 | G8: 15

Sheet Report 2
A1: BÁO CÁO CÁC CÔNG VIỆC PHÒNG BIM (XD-MEP/HT)
A2: STT | B2: Công việc chính | C2: Tổng số đầu việc | D2: Số đầu việc đang thực hiện | E2: Số đầu việc hoàn thành | F2: Số đầu việc tạm dừng | G2: Số đầu việc quá hạn
A3: 1 | B3: Xây dựng HTTC BIM | C3: =SUM(D3:G3) -> 40 | D3: 10 | E3: 10 | F3: 10 | G3: 10
A4: 2 | B4: Đào tạo BIM | C4: =SUM(D4:G4) -> 44 | D4: 11 | E4: 11 | F4: 11 | G4: 11
A5: 3 | B5: Quản lý BIM | C5: =SUM(D5:G5) -> 48 | D5: 12 | E5: 12 | F5: 12 | G5: 12
A6: 4 | B6: Thanh tra BIM | C6: =SUM(D6:G6) -> 52 | D6: 13 | E6: 13 | F6: 13 | G6: 13
A7: 5 | B7: Phát triển BIM Tools | C7: =SUM(D7:G7) -> 56 | D7: 14 | E7: 14 | F7: 14 | G7: 14
A8: 6 | B8: Quản lý phần mềm | C8: =SUM(D8:G8) -> 60 | D8: 15 | E8: 15 | F8: 15 | G8: 15

Sheet Report 3
A1: BÁO CÁO CÁC CÔNG VIỆC TỪNG NHÂN SỰ
A2: STT | B2: Nhân sự | C2: Tổng số đầu việc | D2: Số đầu việc đang thực hiện | E2: Số đầu việc hoàn thành | F2: Số đầu việc tạm dừng | G2: Số đầu việc quá hạn
A3: 1 | C3: =SUM(D3:G3) -> 40 | D3: 10 | E3: 10 | F3: 10 | G3: 10
A4: 2 | C4: =SUM(D4:G4) -> 44 | D4: 11 | E4: 11 | F4: 11 | G4: 11
A5: 3 | C5: =SUM(D5:G5) -> 48 | D5: 12 | E5: 12 | F5: 12 | G5: 12
A6: 4 | C6: =SUM(D6:G6) -> 52 | D6: 13 | E6: 13 | F6: 13 | G6: 13
A7: 5 | C7: =SUM(D7:G7) -> 56 | D7: 14 | E7: 14 | F7: 14 | G7: 14
A8: 6 | C8: =SUM(D8:G8) -> 60 | D8: 15 | E8: 15 | F8: 15 | G8: 15
A9: 7
A10: 8
A11: 9
A12: 10
A13: 11
A14: 12
A15: 13
A16: 14
A17: 15
A18: 16
A19: 17
A20: 18
... A27: 25

Sheet Report 4
A1: BÁO CÁO ĐỊNH MỨC CÁC CÔNG VIỆC TỪNG NHÂN SỰ
A2: STT | B2: Nhân sự | C2: Khởi tạo mô hình BIM | D2: Tạo lập mô hình BIM TKCS nộp CQNN | E2: Tạo lập mô hình BIM TKKT/FEED nộp CQNN | F2: Tạo lập mô hình BIM TKBVTC | G2: Tạo lập thư viện | H2: KSCL mô hình BIM | I2: Tổng hợp số liệu QH | J2: Tổng hợp số liệu TT | K2: Triển khai HS TKCS | L2: Cập nhật thông tin mô hình BIM | M2: Xuất khối lượng từ mô hình BIM
A3: 1 | B3: Hà Minh Luân | C3: 10 | D3: 10 | E3: 10 | F3: 10 | G3: 10 | H3: 10 | I3: 10 | J3: 10 | K3: 10 | L3: 10 | M3: 10
A4: 2 | B4: Mai Hồng Hạnh | C4: 10 | D4: 10 | E4: 10 | F4: 10 | G4: 10 | H4: 10 | I4: 10 | J4: 10 | K4: 10 | L4: 10 | M4: 10
A5: 3 | B5: Lý Huy Thành | C5: 10 | D5: 10 | E5: 10 | F5: 10 | G5: 10 | H5: 10 | I5: 10 | J5: 10 | K5: 10 | L5: 10 | M5: 10
A6: 4 | B6: Nguyễn Hải Nam | C6: 10 | D6: 10 | E6: 10 | F6: 10 | G6: 10 | H6: 10 | I6: 10 | J6: 10 | K6: 10 | L6: 10 | M6: 10
A7: 5 | B7: Đỗ Minh Ngọc | C7: 10 | D7: 10 | E7: 10 | F7: 10 | G7: 10 | H7: 10 | I7: 10 | J7: 10 | K7: 10 | L7: 10 | M7: 10
A8: 6 | B8: Trần Văn Diện | C8: 10 | D8: 10 | E8: 10 | F8: 10 | G8: 10 | H8: 10 | I8: 10 | J8: 10 | K8: 10 | L8: 10 | M8: 10
A9: 7 | B9: Đặng Minh Quang | C9: 10 | D9: 10 | E9: 10 | F9: 10 | G9: 10 | H9: 10 | I9: 10 | J9: 10 | K9: 10 | L9: 10 | M9: 10
A10: 8 | B10: Trần Văn Toản | C10: 10 | D10: 10 | E10: 10 | F10: 10 | G10: 10 | H10: 10 | I10: 10 | J10: 10 | K10: 10 | L10: 10 | M10: 10
A11: 9
A12: 10
A13: 11
A14: 12
A15: 13
A16: 14
A17: 15
A18: 16
A19: 17
A20: 18
A21: 19
A22: 20
... A27: 25

Sheet Data
A1: DATA CÔNG VIỆC
A2: STT | B2: Xây dựng HTTC BIM | E2: Đào tạo BIM | H2: Quản lý BIM | L2: Thanh tra BIM | M2: Phát triển BIM Tools | P2: Quản lý phần mềm | S2: Công việc khác | V2: Other
B3: Level 2 | C3: Level 3 | D3: Level 5 | E3: Level 2 | F3: Level 3 | G3: Level 5 | H3: Level 2 | I3: Level 3 | J3: Quy mô công trình | K3: Level 5 | L3: Level 5 | M3: Level 2 | N3: Level 3 | O3: Level 5 | P3: Level 2 | Q3: Level 3 | R3: Level 5 | S3: Level 2 | T3: Level 3 | U3: Level 5 | V3: Bộ môn | W3: Giai đoạn | X3: Mức độ ưu tiên | Y3: Nhân sự
A4: 1 | B4: Quy định | C4: Quy định triển khai BIM | D4: Rà soát | E4: HTTC BIM | F4: HTTC BIM | G4: Khảo sát nhu cầu | H4: All | I4: All | J4: N/A | K4: Set up hệ thống DR3 | L4: Đánh giá KSCL mô hình | M4: Revit | N4: Ván khuôn | O4: Ghi nhận yêu cầu và tìm hiểu nghiệp vụ | R4: Khảo sát nhu cầu và cân đối số lượng | S4: Công việc khác | T4: Công việc khác | U4: Setup hệ thống quản lý công việc | V4: BIM | W4: Concept | X4: Cao | Y4: All
A5: 2 | B5: Các phụ lục | C5: Phụ lục 1_Tiến trình phối hợp mô hình BIM giữa các bộ phận | D5: Biên soạn mới | E5: CDE | F5: Quản lý HSTK | G5: Lập kế hoạch và chương trình | H5: B.DSHNQN.DMF | I5: Bãi đỗ tàu qua đêm Cổ Loa | J5: Điền tổng Diện tích sàn | K5: KSCL DR3 | L5: Lấy ý kiến xác nhận lỗi | M5: Revit | N5: Công cụ định vị | O5: Lên và Trình PD phương án | R5: Lập ngân sách trang bị PM | U5: Họp nội bộ | V5: BIM XD | W5: TKCS | X5: Trung bình | Y5: Hà Minh Luân
A6: 3 | B6: Các phụ lục | C6: Phụ lục 2_Cấu trúc và phân quyền thư mục các dự án trên Server VTK | E6: CDE | F6: Quản lý HSTC | G6: Triển khai đào tạo | H6: B.DSHNQN.DMF | I6: Depot Hạ Long Xanh | J6: Điền tổng Diện tích sàn | K6: Set up hệ thống CDE | L6: Lập BB XLVP | M6: Revit | N6: ViewSheets(Tạo Sheets) | O6: Thực hiện Code | R6: Trình PD chủ trương trang bị PM | U6: Họp với BP khác | V6: BIM MEPF | W6: FEED | X6: Thấp | Y6: Mai Hồng Hạnh
A7: 4 | B7: Các phụ lục | C7: Phụ lục 3_Cấu trúc và phân quyền thư mục CDE | E7: CDE | F7: Mô đun 3 | G7: Tổ chức thi và đánh giá | H7: B.DSHNQN.STA | I7: Nhà ga Cổ Loa | J7: Điền tổng Diện tích sàn | K7: KSCL CDE | M7: Revit | N7: Đào/Đặp | O7: Chạy thử và Đánh giá | R7: Thẩm định giá và bổ nhiệm NCC | V7: BIM HT | W7: TKKT | Y7: Lý Huy Thành
A8: 5 | B8: Các phụ lục | C8: Phụ lục 4_Các quy trình phê duyệt hồ sơ trên CDE | E8: Công cụ tạo lập mô hình | F8: Revit cơ bản | G8: Báo cáo đào tạo | H8: B.DSHNQN.STA | I8: Nhà ga Gia Bình | J8: Điền tổng Diện tích sàn | K8: Điều phối CDE | M8: Revit | N8: Selection Tools | O8: Fix lỗi | R8: Lập PR-PO | V8: BIM IT | W8: TKBVTC | Y8: Nguyễn Hải Nam
A9: 6 | B9: Các phụ lục | C9: Phụ lục 5_Quy ước đặt tên tệp tin và đánh mã bản vẽ | E9: Công cụ tạo lập mô hình | F9: Revit nâng cao | H9: B.DSHNQN.STA | I9: Nhà ga Hạ Long Xanh | J9: Điền tổng Diện tích sàn | K9: Khởi tạo mô hình BIM | M9: Revit | N9: Select By Parameter | O9: Hướng dẫn sử dụng | R9: Ký kết HĐ | V9: KT | W9: Thi công | Y9: Đỗ Minh Ngọc
A10: 7 | B10: Các phụ lục | C10: Phụ lục 6_Quy trình kiểm khớp và ma trận va chạm mẫu | E10: Công cụ tạo lập mô hình | F10: Civil3D và InfraWorks | H10: B.DSHNQN.STA | I10: Nhà ga Ninh Xá | J10: Điền tổng Diện tích sàn | K10: Tạo lập mô hình BIM | M10: Revit | N10: Highlight Model | O10: Xuất bản | R10: BB nghiệm thu | V10: KC | W10: Hoàn công | Y10: Trần Văn Diện
A11: 8 | B11: Các phụ lục | C11: Phụ lục 7_Quy định màu sắc các đối tượng trong mô hình BIM | E11: Công cụ phối hợp mô hình | F11: Navisworks | H11: B.DSHNQN.STA | I11: Nhà ga Yên Tử | J11: Điền tổng Diện tích sàn | K11: Tạo lập thư viện | M11: Revit | N11: Tag Plantings | R11: Thanh toán cho NCC | V11: DI | W11: Vận hành | Y11: Đặng Minh Quang
A12: 9 | B12: Các phụ lục | C12: Phụ lục 8_Các khung nhìn mẫu View Template | E12: BIM Tools | F12: BIM Tools | H12: B.HNO.GL.VSC | I12: Trường PTLC hệ Cambride Lô B5-TH01 | J12: Điền tổng Diện tích sàn | K12: KSCL mô hình BIM | M12: Revit | N12: Central File | R12: Phân phối License | V12: DN | Y12: Trần Văn Toản
A13: 10 | B13: Các phụ lục | C13: Phụ lục 9_Quy ước đánh mã Tỉnh Thành phố | H13: B.HNO.GL.VUNI | I13: Trường Vinuni - Tòa M | J13: Điền tổng Diện tích sàn | K13: Điều phối BIM | M13: Revit | N13: Auto Place | V13: NU | Y13: Vũ Thị Thêu
A14: 11 | B14: Các phụ lục | C14: Phụ lục 10_Tiêu chuẩn LOD cho Kiến trúc | H14: B.HNO.GL.VUNI | I14: Trường Vinuni - Tòa P | J14: Điền tổng Diện tích sàn | K14: Tổng hợp số liệu QH | M14: Revit | N14: Auto Joins | V14: PC | Y14: Ngô Tuấn Vũ
A15: 12 | B15: Các phụ lục | C15: Phụ lục 11_Tiêu chuẩn LOD cho Kết cấu | H15: B.HNO.GL.VUNI | I15: Trường Vinuni - Tòa Q, R, S | J15: Điền tổng Diện tích sàn | K15: Tổng hợp số liệu TT | M15: Revit | N15: Assign Level | V15: DH | Y15: Nguyễn Văn Hải
A16: 13 | B16: Các phụ lục | C16: Phụ lục 12_Tiêu chuẩn LOD cho MEP | H16: B.HNO.GL.VUNI | I16: Trường Vinuni - Tòa T (KTX) | J16: Điền tổng Diện tích sàn | K16: Triển khai HS TKCS | M16: Revit | N16: Tag Rooms | V16: HT | Y16: Lê Huy Toàn
A17: 14 | B17: Các phụ lục | C17: Phụ lục 13_Tiêu chuẩn LOD cho hạ tầng | H17: B.HNO.GL.VUNI | I17: Trường Vinuni - Tòa U (KTX) | J17: Điền tổng Diện tích sàn | K17: Cập nhật thông tin mô hình BIM | M17: Revit | N17: View Range | V17: MEPF | Y17: Đặng Thái Sơn
A18: 15 | B18: Các phụ lục | C18: Phụ lục 14_Tiêu chuẩn LOD cho trackwork | H18: B.HNO.TMDM.VSC | I18: Trường Cambridge tại lô F3-PTTH1 | J18: Điền tổng Diện tích sàn | K18: Xuất khối lượng từ mô hình BIM | M18: Revit | N18: Auto Numbering | Y18: Phan Trường Giang
A19: 16 | B19: Các phụ lục | C19: Phụ lục 15_Tiêu chuẩn LOD cho Cầu | H19: B.HNO.VHCL.VSC | I19: A7-NT, A7-CS và PT-02 | J19: Điền tổng Diện tích sàn | M19: Revit | N19: Override CropView | Y19: Nguyễn Ngọc Cảnh
A20: 17 | B20: Các phụ lục | C20: Phụ lục 16_Phạm vi mô hình BIM và xuất khối lượng | H20: B.HNO.VHOHN.KS | I20: Lô đất B9-DV-02 | J20: Điền tổng Diện tích sàn | M20: Revit | N20: Remove Revit Link | Y20: Vũ Hải Phong
A21: 18 | B21: Các phụ lục | C21: Phụ lục 17_Checklist KSCL Mô hình | H21: B.HNO.VHOHN.SVD | I21: SVĐ lô đất TDTT01 | J21: Điền tổng Diện tích sàn | M21: Revit | N21: Update Element Properties | Y21: Tạ Bạch Hưng
A22: 19 | B22: Các phụ lục | C22: Phụ lục 18_Checklist KSCL CDE | H22: B.HPH.VYHP.VSC | I22: Trường VSC B2.THPT02 | J22: Điền tổng Diện tích sàn | M22: Revit | N22: Copy Elements From Link | Y22: Hoàng Bảo Sơn
A23: 20 | B23: Các phụ lục | C23: Phụ lục 19_Chi tiết phân loại các nhóm lỗi va chạm trong mô hình BIM | H23: B.HYE.NOXHHY.CT | I23: NOXH01 (04 tòa) | J23: Điền tổng Diện tích sàn | M23: Revit | N23: Export Schedules to Excel | Y23: Nguyễn Thế Anh
A24: 21 | B24: Các biểu mẫu | C24: Biểu mẫu 1_Mẫu tệp tin BEP cho các dự án áp dụng BIM | H24: B.HYE.NOXHHY.CT | I24: NOXH02 (09 tòa) | J24: Điền tổng Diện tích sàn | M24: Revit | N24: Export Sheets | Y24: Lê Văn Trí
A25: 22 | B25: Các biểu mẫu | C25: Biểu mẫu 2_Danh sách nhân sự của dự án | H25: B.HYE.NOXHHY.CT | I25: NOXH03 (05 tòa) | J25: Điền tổng Diện tích sàn | M25: Revit | N25: Xuất Familys | Y25: Nguyễn Tuấn Cường
A26: 23 | B26: Các biểu mẫu | C26: Biểu mẫu 3_Mẫu danh mục tệp tin và bản vẽ | H26: B.HYE.NOXHHY.CT | I26: NOXH04 (07 tòa) | J26: Điền tổng Diện tích sàn | M26: Revit | N26: Xuất Khối Lượng | Y26: Hoàng Đình Trung
A27: 24 | B27: Các biểu mẫu | C27: Biểu mẫu 4_Các bảng thống kê mẫu KT | H27: B.HYE.NOXHPH.NX | I27: Nhà xe BDX-01 | J27: Điền tổng Diện tích sàn | M27: Revit | N27: Convert Grid 3D to 2D | Y27: Nguyễn Văn Tuyên
A28: 25 | B28: Các biểu mẫu | C28: Biểu mẫu 5_Các bảng thống kê mẫu KC | H28: B.HYE.NOXHPH.NX | I28: Nhà xe BDX-05 | J28: Điền tổng Diện tích sàn | M28: Revit | N28: Bubble On/Off | Y28: Nguyễn Thanh Phương
A29: 26 | B29: Các biểu mẫu | C29: Biểu mẫu 6_Các bảng thống kê mẫu Điện | H29: B.HYE.PVF | I29: Nhà thi đấu TDTT03 | J29: Điền tổng Diện tích sàn | M29: Revit | N29: Transfer By Link
A30: 27 | B30: Các biểu mẫu | C30: Biểu mẫu 7_Các bảng thống kê mẫu Điện nhẹ | H30: B.HYE.PVF | I30: Sân vận động TDTT01 | J30: Điền tổng Diện tích sàn | M30: Revit | N30: Load Family
A31: 28 | B31: Các biểu mẫu | C31: Biểu mẫu 8_Các bảng thống kê mẫu Cấp thoát nước | H31: B.QNI.HLX.CT | I31: Hầm lô B03.2-CCCT-01 | J31: Điền tổng Diện tích sàn | M31: Revit | N31: Remove Filter
A32: 29 | B32: Các biểu mẫu | C32: Biểu mẫu 9_Các bảng thống kê mẫu ĐHTG | H32: B.QNI.HLX.CT | I32: Hầm lô B03.2-CCCT-02 | J32: Điền tổng Diện tích sàn | M32: Revit | N32: Chuyển giá trị Parameter
A33: 30 | B33: Các biểu mẫu | C33: Biểu mẫu 10_Các bảng thống kê mẫu PCCC | H33: B.QNI.HLX.CT | I33: Hầm lô B03.2-CCCT-03 | J33: Điền tổng Diện tích sàn | M33: Revit | N33: Tồng Hợp Số Liệu
A34: 31 | B34: Các biểu mẫu | C34: Biểu mẫu 11_Phiếu yêu cầu hỗ trợ BIM | H34: B.QNI.HLX.CT | I34: Hầm lô B03.4-CCCT-01 | J34: Điền tổng Diện tích sàn | M34: Revit | N34: Tag Diện Tích
A35: 32 | B35: Quy định công tác thanh tra BIM | C35: Quy định công tác thanh tra BIM | H35: B.QNI.HLX.CT | I35: Hầm lô B03.4-CCCT-02 | J35: Điền tổng Diện tích sàn | M35: Revit | N35: Move Tag to Center
A36: 33 | H36: B.QNI.HLX.CT | I36: Hầm lô B03.4-CCCT-03 | J36: Điền tổng Diện tích sàn | M36: Revit | N36: Room Finishing
A37: 34 | H37: B.QNI.HLX.CT | I37: Tháp Z35 | J37: Điền tổng Diện tích sàn | M37: Revit | N37: Wall By Boundary
A38: 35 | H38: B.QNI.HLXHL.VMM | I38: VC MEGAMALL LÔ ĐẤT B02.3-TMĐ-01 | J38: Điền tổng Diện tích sàn | M38: Revit | N38: Remove Paint
A39: 36 | H39: B.QNI.HLXHL.VP | I39: Tòa văn phòng 35 tầng (Lô đất B03.5-TMĐ-01) | J39: Điền tổng Diện tích sàn | M39: Revit | N39: Edit Layer
A40: 37 | H40: B.QNI.HLXHL.VSC | I40: Trường học các lô đất A2-MG-06, A2-TH-05, A2-CS-04 | J40: Điền tổng Diện tích sàn | M40: Revit | N40: Clear Duplicates
...

Sheet Bảng 1
C1: BẢNG GIAO VIỆC XÂY DỰNG HTTC BIM
A2: Sum ID | B2: Sub ID | C2: Level 1 | D2: Level 2 | E2: Level 3 | F2: Level 4 | G2: Level 5 | H2: Mức độ ưu tiên | I2: Nhân sự thực hiện 01 | J2: Nhân sự thực hiện 02 | K2: Nhân sự thực hiện 03 | L2: Bắt đầu | M2: Kết thúc
A3: ="1."&D3&"."&B3 -> 1.Quy định.001 | B3: 001 | C3: Xây dựng HTTC BIM | D3: Quy định | E3: Quy định triển khai BIM | F3: BIM | G3: Rà soát | H3: Thấp | I3: All | L3: 46174 | M3: 46280
A4: ="1."&D4&"."&B4 -> 1.Các phụ lục.002 | B4: 002 | C4: Xây dựng HTTC BIM | D4: Các phụ lục | E4: Phụ lục 1_Tiến trình phối hợp mô hình BIM giữa các bộ phận | F4: BIM | G4: Rà soát | H4: Thấp | I4: All | L4: 46174 | M4: 46280
A5: ="1."&D5&"."&B5 -> 1.Các phụ lục.003 | B5: 003 | C5: Xây dựng HTTC BIM | D5: Các phụ lục | E5: Phụ lục 2_Cấu trúc và phân quyền thư mục các dự án trên Server VTK | F5: BIM | G5: Rà soát | H5: Thấp | I5: All | L5: 46174 | M5: 46280
A6: ="1."&D6&"."&B6 -> 1.Các phụ lục.004 | B6: 004 | C6: Xây dựng HTTC BIM | D6: Các phụ lục | E6: Phụ lục 3_Cấu trúc và phân quyền thư mục CDE | F6: BIM | G6: Rà soát | H6: Thấp | I6: All | L6: 46174 | M6: 46280
A7: ="1."&D7&"."&B7 -> 1.Các phụ lục.005 | B7: 005 | C7: Xây dựng HTTC BIM | D7: Các phụ lục | E7: Phụ lục 4_Các quy trình phê duyệt hồ sơ trên CDE | F7: BIM | G7: Rà soát | H7: Thấp | I7: All | L7: 46174 | M7: 46280
A8: ="1."&D8&"."&B8 -> 1.Các phụ lục.006 | B8: 006 | C8: Xây dựng HTTC BIM | D8: Các phụ lục | E8: Phụ lục 5_Quy ước đặt tên tệp tin và đánh mã bản vẽ | F8: BIM | G8: Rà soát | H8: Thấp | I8: All | L8: 46174 | M8: 46280
A9: ="1."&D9&"."&B9 -> 1.Các phụ lục.007 | B9: 007 | C9: Xây dựng HTTC BIM | D9: Các phụ lục | E9: Phụ lục 6_Quy trình kiểm khớp và ma trận va chạm mẫu | F9: BIM | G9: Rà soát | H9: Thấp | I9: All | L9: 46174 | M9: 46280
A10: ="1."&D10&"."&B10 -> 1.Các phụ lục.008 | B10: 008 | C10: Xây dựng HTTC BIM | D10: Các phụ lục | E10: Phụ lục 7_Quy định màu sắc các đối tượng trong mô hình BIM | F10: BIM | G10: Rà soát | H10: Thấp | I10: All | L10: 46174 | M10: 46280
A11: ="1."&D11&"."&B11 -> 1.Các phụ lục.009 | B11: 009 | C11: Xây dựng HTTC BIM | D11: Các phụ lục | E11: Phụ lục 8_Các khung nhìn mẫu View Template | F11: BIM | G11: Rà soát | H11: Thấp | I11: All | L11: 46174 | M11: 46280
A12: ="1."&D12&"."&B12 -> 1.Các phụ lục.010 | B12: 010 | C12: Xây dựng HTTC BIM | D12: Các phụ lục | E12: Phụ lục 9_Quy ước đánh mã Tỉnh Thành phố | F12: BIM | G12: Rà soát | H12: Thấp | I12: All | L12: 46174 | M12: 46280
A13: ="1."&D13&"."&B13 -> 1.Các phụ lục.011 | B13: 011 | C13: Xây dựng HTTC BIM | D13: Các phụ lục | E13: Phụ lục 10_Tiêu chuẩn LOD cho Kiến trúc | F13: BIM | G13: Rà soát | H13: Thấp | I13: All | L13: 46174 | M13: 46280
A14: ="1."&D14&"."&B14 -> 1.Các phụ lục.012 | B14: 012 | C14: Xây dựng HTTC BIM | D14: Các phụ lục | E14: Phụ lục 11_Tiêu chuẩn LOD cho Kết cấu | F14: BIM | G14: Rà soát | H14: Thấp | I14: All | L14: 46174 | M14: 46280
... A34: ="1."&D34&"."&B34 -> 1.Quy định công tác thanh tra BIM.032 | B34: 032 | C34: Xây dựng HTTC BIM | D34: Quy định công tác thanh tra BIM | E34: Quy định công tác thanh tra BIM | F34: BIM | G34: Rà soát | H34: Thấp | I34: All | L34: 46174 | M34: 46280

Sheet Bảng 2
C1: BẢNG GIAO VIỆC ĐÀO TẠO BIM
A2: Sum ID | B2: Sub ID | C2: Level 1 | D2: Level 2 | E2: Level 3 | F2: Level 4 | G2: Level 5 | H2: Mức độ ưu tiên | I2: Nhân sự thực hiện 01 | J2: Nhân sự thực hiện 02 | K2: Nhân sự thực hiện 03 | L2: Bắt đầu | M2: Kết thúc
A3: ="2."&D3&"."&B3 -> 2.Công cụ tạo lập mô hình.001 | B3: =TEXT(COUNTIFS($C$3:C3,C3,$D$3:D3,D3),"000") -> 001 | C3: Đào tạo BIM | D3: Công cụ tạo lập mô hình | E3: Revit cơ bản | F3: KT | G3: Lập kế hoạch và chương trình | H3: Cao | I3: Nguyễn Hải Nam | J3: Trần Văn Diện | L3: 46185 | M3: 46192
A4: ="2."&D4&"."&B4 -> 2.Công cụ tạo lập mô hình.002 | B4: =TEXT(COUNTIFS($C$3:C4,C4,$D$3:D4,D4),"000") -> 002 | C4: Đào tạo BIM | D4: Công cụ tạo lập mô hình | E4: Revit cơ bản | F4: KT | G4: Triển khai đào tạo | H4: Cao | I4: Nguyễn Hải Nam | J4: Trần Văn Diện
A5: ="2."&D5&"."&B5 -> 2.Công cụ tạo lập mô hình.003 | B5: =TEXT(COUNTIFS($C$3:C5,C5,$D$3:D5,D5),"000") -> 003 | C5: Đào tạo BIM | D5: Công cụ tạo lập mô hình | E5: Revit cơ bản | F5: KT | G5: Tổ chức thi và đánh giá | H5: Cao | I5: Nguyễn Hải Nam | J5: Trần Văn Diện
A6: ="2."&D6&"."&B6 -> 2.Công cụ tạo lập mô hình.004 | B6: =TEXT(COUNTIFS($C$3:C6,C6,$D$3:D6,D6),"000") -> 004 | C6: Đào tạo BIM | D6: Công cụ tạo lập mô hình | E6: Revit cơ bản | F6: KT | G6: Báo cáo đào tạo | H6: Cao | I6: Nguyễn Hải Nam | J6: Trần Văn Diện
A7: ="2."&D7&"."&B7 -> 2.Công cụ tạo lập mô hình.005 | B7: =TEXT(COUNTIFS($C$3:C7,C7,$D$3:D7,D7),"000") -> 005 | C7: Đào tạo BIM | D7: Công cụ tạo lập mô hình | E7: Revit cơ bản | F7: BIM MEPF | G7: Tổ chức thi và đánh giá | H7: Cao | I7: Phan Trường Giang | L7: 46178 | M7: 46185
A8: ="2."&D8&"."&B8 -> 2.Công cụ tạo lập mô hình.006 | B8: =TEXT(COUNTIFS($C$3:C8,C8,$D$3:D8,D8),"000") -> 006 | C8: Đào tạo BIM | D8: Công cụ tạo lập mô hình | E8: Revit cơ bản | F8: BIM MEPF | G8: Khảo sát nhu cầu | H8: Cao | I8: Phan Trường Giang | L8: 46188 | M8: 46188
A9: ="2."&D9&"."&B9 -> 2.Công cụ tạo lập mô hình.007 | B9: =TEXT(COUNTIFS($C$3:C9,C9,$D$3:D9,D9),"000") -> 007 | C9: Đào tạo BIM | D9: Công cụ tạo lập mô hình | E9: Revit cơ bản | F9: BIM MEPF | G9: Báo cáo đào tạo | H9: Cao | I9: Ngô Tuấn Vũ | L9: 46188 | M9: 46188
A10: ="2."&D10&"."&B10 -> 2.CDE.001 | B10: =TEXT(COUNTIFS($C$3:C10,C10,$D$3:D10,D10),"000") -> 001 | C10: Đào tạo BIM | D10: CDE | E10: Quản lý HSTK | F10: BIM | G10: Khảo sát nhu cầu | H10: Trung bình | I10: Lý Huy Thành | J10: Ngô Tuấn Vũ | L10: 46174 | M10: 46179
A11: ="2."&D11&"."&B11 -> 2.CDE.002 | B11: =TEXT(COUNTIFS($C$3:C11,C11,$D$3:D11,D11),"000") -> 002 | C11: Đào tạo BIM | D11: CDE | E11: Quản lý HSTC | F11: BIM | G11: Khảo sát nhu cầu | H11: Trung bình | I11: Lý Huy Thành | J11: Ngô Tuấn Vũ | L11: 46174 | M11: 46179
A12: ="2."&D12&"."&B12 -> 2.Công cụ tạo lập mô hình.008 | B12: =TEXT(COUNTIFS($C$3:C12,C12,$D$3:D12,D12),"000") -> 008 | C12: Đào tạo BIM | D12: Công cụ tạo lập mô hình | E12: Revit cơ bản | F12: BIM | G12: Khảo sát nhu cầu | H12: Trung bình | I12: Lý Huy Thành | J12: Ngô Tuấn Vũ | L12: 46174 | M12: 46179
A13: ="2."&D13&"."&B13 -> 2.Công cụ tạo lập mô hình.009 | B13: =TEXT(COUNTIFS($C$3:C13,C13,$D$3:D13,D13),"000") -> 009 | C13: Đào tạo BIM | D13: Công cụ tạo lập mô hình | E13: Revit nâng cao | F13: BIM | G13: Khảo sát nhu cầu | H13: Trung bình | I13: Lý Huy Thành | L13: 46174 | M13: 46179
A14: ="2."&D14&"."&B14 -> 2.Công cụ phối hợp mô hình.001 | B14: =TEXT(COUNTIFS($C$3:C14,C14,$D$3:D14,D14),"000") -> 001 | C14: Đào tạo BIM | D14: Công cụ phối hợp mô hình | E14: Navisworks | F14: BIM | G14: Khảo sát nhu cầu | H14: Trung bình | I14: Lý Huy Thành | J14: Ngô Tuấn Vũ | L14: 46174 | M14: 46179
A15: ="2."&D15&"."&B15 -> 2.BIM Tools.001 | B15: =TEXT(COUNTIFS($C$3:C15,C15,$D$3:D15,D15),"000") -> 001 | C15: Đào tạo BIM | D15: BIM Tools | E15: BIM Tools | F15: BIM | G15: Khảo sát nhu cầu | H15: Trung bình | I15: Nguyễn Thanh Phương | J15: Lê Huy Toàn | L15: 46174 | M15: 46179

Sheet Bảng 3
C1: BẢNG GIAO VIỆC QUẢN LÝ BIM
A2: Sum ID | B2: Sub ID | C2: Level 1 | D2: Level 2 | E2: Level 3 | F2: Level 4 | G2: Level 5 | H2: Giai đoạn | I2: Mức độ ưu tiên | J2: Nhân sự thực hiện 01 | K2: Nhân sự thực hiện 02 | L2: Nhân sự thực hiện 03 | M2: Bắt đầu | N2: Kết thúc | O2: Fillter nhân sự
A3: ="3."&D3&"."&B3 -> 3.B.DSHNQN.DMF.101 | B3: =TEXT( COUNTIFS($C$3:C3,C3,$D$3:D3,D3,$F$3:F3,F3) + IF(F3="KT",100, IF(F3="KC",200, IF(F3="BIM MEPF",300,0))),"000") -> 101 | C3: Quản lý BIM | D3: B.DSHNQN.DMF | E3: Bãi đỗ tàu qua đêm Cổ Loa | F3: KT | G3: Tạo lập mô hình BIM | H3: TKBVTC | I3: Cao | J3: Trần Văn Diện | K3: Đặng Minh Quang | O3: =J3&", "&K3&", "&L3 -> Trần Văn Diện, Đặng Minh Quang,
A4: ="3."&D4&"."&B4 -> 3.B.DSHNQN.DMF.201 | B4: =TEXT(COUNTIFS($C$3:C4,C4,$D$3:D4,D4,$F$3:F4,F4)+IF(F4="KT",100,IF(F4="KC",200,IF(F4="DI",300,IF(F4="DN",400,IF(F4="NU",500,IF(F4="DH",600,IF(F4="PC",700,0))))))),"000") -> 201 | C4: Quản lý BIM | D4: B.DSHNQN.DMF | E4: Bãi đỗ tàu qua đêm Cổ Loa | F4: KC | G4: Tạo lập mô hình BIM | H4: TKBVTC | I4: Cao | J4: Trần Văn Diện | K4: Đặng Minh Quang | O4: =J4&", "&K4&", "&L4 -> Trần Văn Diện, Đặng Minh Quang,
A5: ="3."&D5&"."&B5 -> 3.B.DSHNQN.DMF.301 | B5: =TEXT(COUNTIFS($C$3:C5,C5,$D$3:D5,D5,$F$3:F5,F5)+IF(F5="KT",100,IF(F5="KC",200,IF(F5="DI",300,IF(F5="DN",400,IF(F5="NU",500,IF(F5="DH",600,IF(F5="PC",700,0))))))),"000") -> 301 | C5: Quản lý BIM | D5: B.DSHNQN.DMF | E5: Bãi đỗ tàu qua đêm Cổ Loa | F5: DI | G5: KSCL mô hình BIM | H5: TKBVTC | I5: Cao | J5: Đặng Thái Sơn | M5: 46198 | N5: 46230 | O5: =J5&", "&K5&", "&L5 -> Đặng Thái Sơn, ,
A6: ="3."&D6&"."&B6 -> 3.B.DSHNQN.DMF.401 | B6: =TEXT(COUNTIFS($C$3:C6,C6,$D$3:D6,D6,$F$3:F6,F6)+IF(F6="KT",100,IF(F6="KC",200,IF(F6="DI",300,IF(F6="DN",400,IF(F6="NU",500,IF(F6="DH",600,IF(F6="PC",700,0))))))),"000") -> 401 | C6: Quản lý BIM | D6: B.DSHNQN.DMF | E6: Bãi đỗ tàu qua đêm Cổ Loa | F6: DN | G6: KSCL mô hình BIM | H6: TKBVTC | I6: Cao | J6: Đặng Thái Sơn | M6: 46198 | N6: 46230 | O6: =J6&", "&K6&", "&L6 -> Đặng Thái Sơn, ,
A7: ="3."&D7&"."&B7 -> 3.B.DSHNQN.DMF.501 | B7: =TEXT(COUNTIFS($C$3:C7,C7,$D$3:D7,D7,$F$3:F7,F7)+IF(F7="KT",100,IF(F7="KC",200,IF(F7="DI",300,IF(F7="DN",400,IF(F7="NU",500,IF(F7="DH",600,IF(F7="PC",700,0))))))),"000") -> 501 | C7: Quản lý BIM | D7: B.DSHNQN.DMF | E7: Bãi đỗ tàu qua đêm Cổ Loa | F7: NU | G7: KSCL mô hình BIM | H7: TKBVTC | I7: Cao | J7: Đặng Thái Sơn | M7: 46198 | N7: 46230 | O7: =J7&", "&K7&", "&L7 -> Đặng Thái Sơn, ,
A8: ="3."&D8&"."&B8 -> 3.B.DSHNQN.DMF.601 | B8: =TEXT(COUNTIFS($C$3:C8,C8,$D$3:D8,D8,$F$3:F8,F8)+IF(F8="KT",100,IF(F8="KC",200,IF(F8="DI",300,IF(F8="DN",400,IF(F8="NU",500,IF(F8="DH",600,IF(F8="PC",700,0))))))),"000") -> 601 | C8: Quản lý BIM | D8: B.DSHNQN.DMF | E8: Bãi đỗ tàu qua đêm Cổ Loa | F8: DH | G8: KSCL mô hình BIM | H8: TKBVTC | I8: Cao | J8: Đặng Thái Sơn | M8: 46198 | N8: 46230 | O8: =J8&", "&K8&", "&L8 -> Đặng Thái Sơn, ,
A9: ="3."&D9&"."&B9 -> 3.B.DSHNQN.DMF.701 | B9: =TEXT(COUNTIFS($C$3:C9,C9,$D$3:D9,D9,$F$3:F9,F9)+IF(F9="KT",100,IF(F9="KC",200,IF(F9="DI",300,IF(F9="DN",400,IF(F9="NU",500,IF(F9="DH",600,IF(F9="PC",700,0))))))),"000") -> 701 | C9: Quản lý BIM | D9: B.DSHNQN.DMF | E9: Bãi đỗ tàu qua đêm Cổ Loa | F9: PC | G9: KSCL mô hình BIM | H9: TKBVTC | I9: Cao | J9: Đặng Thái Sơn | M9: 46198 | N9: 46230 | O9: =J9&", "&K9&", "&L9 -> Đặng Thái Sơn, ,
A10: ="3."&D10&"."&B10 -> 3.B.DSHNQN.DMF.102 | B10: =TEXT(COUNTIFS($C$3:C10,C10,$D$3:D10,D10,$F$3:F10,F10)+IF(F10="KT",100,IF(F10="KC",200,IF(F10="DI",300,IF(F10="DN",400,IF(F10="NU",500,IF(F10="DH",600,IF(F10="PC",700,0))))))),"000") -> 102 | C10: Quản lý BIM | D10: B.DSHNQN.DMF | E10: Depot Hạ Long Xanh | F10: KT | G10: Tạo lập mô hình BIM | H10: TKBVTC | I10: Cao | J10: Trần Văn Toản | K10: Trần Văn Diện | M10: 46114 | N10: 46248 | O10: =J10&", "&K10&", "&L10 -> Trần Văn Toản, Trần Văn Diện,
A11: ="3."&D11&"."&B11 -> 3.B.DSHNQN.DMF.202 | B11: =TEXT(COUNTIFS($C$3:C11,C11,$D$3:D11,D11,$F$3:F11,F11)+IF(F11="KT",100,IF(F11="KC",200,IF(F11="DI",300,IF(F11="DN",400,IF(F11="NU",500,IF(F11="DH",600,IF(F11="PC",700,0))))))),"000") -> 202 | C11: Quản lý BIM | D11: B.DSHNQN.DMF | E11: Depot Hạ Long Xanh | F11: KC | G11: Tạo lập mô hình BIM | H11: TKBVTC | I11: Cao | J11: Trần Văn Toản | K11: Trần Văn Diện | M11: 46154 | N11: 46330 | O11: =J11&", "&K11&", "&L11 -> Trần Văn Toản, Trần Văn Diện,
A12: ="3."&D12&"."&B12 -> 3.B.DSHNQN.DMF.302 | B12: =TEXT(COUNTIFS($C$3:C12,C12,$D$3:D12,D12,$F$3:F12,F12)+IF(F12="KT",100,IF(F12="KC",200,IF(F12="DI",300,IF(F12="DN",400,IF(F12="NU",500,IF(F12="DH",600,IF(F12="PC",700,0))))))),"000") -> 302 | C12: Quản lý BIM | D12: B.DSHNQN.DMF | E12: Depot Hạ Long Xanh | F12: DI | G12: KSCL mô hình BIM | H12: TKBVTC | I12: Cao | J12: Phan Trường Giang | M12: 46186 | N12: 46230 | O12: =J12&", "&K12&", "&L12 -> Phan Trường Giang, ,
A13: ="3."&D13&"."&B13 -> 3.B.DSHNQN.DMF.402 | B13: =TEXT(COUNTIFS($C$3:C13,C13,$D$3:D13,D13,$F$3:F13,F13)+IF(F13="KT",100,IF(F13="KC",200,IF(F13="DI",300,IF(F13="DN",400,IF(F13="NU",500,IF(F13="DH",600,IF(F13="PC",700,0))))))),"000") -> 402 | C13: Quản lý BIM | D13: B.DSHNQN.DMF | E13: Depot Hạ Long Xanh | F13: DN | G13: KSCL mô hình BIM | H13: TKBVTC | I13: Cao | J13: Phan Trường Giang | M13: 46186 | N13: 46230 | O13: =J13&", "&K13&", "&L13 -> Phan Trường Giang, ,
A14: ="3."&D14&"."&B14 -> 3.B.DSHNQN.DMF.502 | B14: =TEXT(COUNTIFS($C$3:C14,C14,$D$3:D14,D14,$F$3:F14,F14)+IF(F14="KT",100,IF(F14="KC",200,IF(F14="DI",300,IF(F14="DN",400,IF(F14="NU",500,IF(F14="DH",600,IF(F14="PC",700,0))))))),"000") -> 502 | C14: Quản lý BIM | D14: B.DSHNQN.DMF | E14: Depot Hạ Long Xanh | F14: NU | G14: KSCL mô hình BIM | H14: TKBVTC | I14: Cao | J14: Phan Trường Giang | M14: 46186 | N14: 46230 | O14: =J14&", "&K14&", "&L14 -> Phan Trường Giang, ,
A15: ="3."&D15&"."&B15 -> 3.B.DSHNQN.DMF.602 | B15: =TEXT(COUNTIFS($C$3:C15,C15,$D$3:D15,D15,$F$3:F15,F15)+IF(F15="KT",100,IF(F15="KC",200,IF(F15="DI",300,IF(F15="DN",400,IF(F15="NU",500,IF(F15="DH",600,IF(F15="PC",700,0))))))),"000") -> 602 | C15: Quản lý BIM | D15: B.DSHNQN.DMF | E15: Depot Hạ Long Xanh | F15: DH | G15: KSCL mô hình BIM | H15: TKBVTC | I15: Cao | J15: Phan Trường Giang | M15: 46186 | N15: 46230 | O15: =J15&", "&K15&", "&L15 -> Phan Trường Giang, ,
A16: ="3."&D16&"."&B16 -> 3.B.DSHNQN.DMF.702 | B16: =TEXT(COUNTIFS($C$3:C16,C16,$D$3:D16,D16,$F$3:F16,F16)+IF(F16="KT",100,IF(F16="KC",200,IF(F16="DI",300,IF(F16="DN",400,IF(F16="NU",500,IF(F16="DH",600,IF(F16="PC",700,0))))))),"000") -> 702 | C16: Quản lý BIM | D16: B.DSHNQN.DMF | E16: Depot Hạ Long Xanh | F16: PC | G16: KSCL mô hình BIM | H16: TKBVTC | I16: Cao | J16: Phan Trường Giang | M16: 46186 | N16: 46230 | O16: =J16&", "&K16&", "&L16 -> Phan Trường Giang, ,
A17: ="3."&D17&"."&B17 -> 3.B.DSHNQN.STA.101 | B17: =TEXT(COUNTIFS($C$3:C17,C17,$D$3:D17,D17,$F$3:F17,F17)+IF(F17="KT",100,IF(F17="KC",200,IF(F17="DI",300,IF(F17="DN",400,IF(F17="NU",500,IF(F17="DH",600,IF(F17="PC",700,0))))))),"000") -> 101 | C17: Quản lý BIM | D17: B.DSHNQN.STA | E17: Nhà ga Cổ Loa | F17: KT | G17: Tạo lập mô hình BIM | H17: TKBVTC | I17: Cao | J17: Trần Văn Diện | M17: 46170 | N17: 46230 | O17: =J17&", "&K17&", "&L17 -> Trần Văn Diện, ,
A18: ="3."&D18&"."&B18 -> 3.B.DSHNQN.STA.301 | B18: =TEXT(COUNTIFS($C$3:C18,C18,$D$3:D18,D18,$F$3:F18,F18)+IF(F18="KT",100,IF(F18="KC",200,IF(F18="DI",300,IF(F18="DN",400,IF(F18="NU",500,IF(F18="DH",600,IF(F18="PC",700,0))))))),"000") -> 301 | C18: Quản lý BIM | D18: B.DSHNQN.STA | E18: Nhà ga Cổ Loa | F18: DI | G18: KSCL mô hình BIM | H18: TKBVTC | I18: Cao | J18: Nguyễn Văn Hải | M18: 46170 | N18: 46230 | O18: =J18&", "&K18&", "&L18 -> Nguyễn Văn Hải, ,
A19: ="3."&D19&"."&B19 -> 3.B.DSHNQN.STA.401 | B19: =TEXT(COUNTIFS($C$3:C19,C19,$D$3:D19,D19,$F$3:F19,F19)+IF(F19="KT",100,IF(F19="KC",200,IF(F19="DI",300,IF(F19="DN",400,IF(F19="NU",500,IF(F19="DH",600,IF(F19="PC",700,0))))))),"000") -> 401 | C19: Quản lý BIM | D19: B.DSHNQN.STA | E19: Nhà ga Cổ Loa | F19: DN | G19: KSCL mô hình BIM | H19: TKBVTC | I19: Cao | J19: Nguyễn Văn Hải | M19: 46170 | N19: 46230 | O19: =J19&", "&K19&", "&L19 -> Nguyễn Văn Hải, ,
A20: ="3."&D20&"."&B20 -> 3.B.DSHNQN.STA.501 | B20: =TEXT(COUNTIFS($C$3:C20,C20,$D$3:D20,D20,$F$3:F20,F20)+IF(F20="KT",100,IF(F20="KC",200,IF(F20="DI",300,IF(F20="DN",400,IF(F20="NU",500,IF(F20="DH",600,IF(F20="PC",700,0))))))),"000") -> 501 | C20: Quản lý BIM | D20: B.DSHNQN.STA | E20: Nhà ga Cổ Loa | F20: NU | G20: KSCL mô hình BIM | H20: TKBVTC | I20: Cao | J20: Nguyễn Văn Hải | M20: 46170 | N20: 46230 | O20: =J20&", "&K20&", "&L20 -> Nguyễn Văn Hải, ,
A21: ="3."&D21&"."&B21 -> 3.B.DSHNQN.STA.601 | B21: =TEXT(COUNTIFS($C$3:C21,C21,$D$3:D21,D21,$F$3:F21,F21)+IF(F21="KT",100,IF(F21="KC",200,IF(F21="DI",300,IF(F21="DN",400,IF(F21="NU",500,IF(F21="DH",600,IF(F21="PC",700,0))))))),"000") -> 601 | C21: Quản lý BIM | D21: B.DSHNQN.STA | E21: Nhà ga Cổ Loa | F21: DH | G21: KSCL mô hình BIM | H21: TKBVTC | I21: Cao | J21: Nguyễn Văn Hải | M21: 46170 | N21: 46230 | O21: =J21&", "&K21&", "&L21 -> Nguyễn Văn Hải, ,
A22: ="3."&D22&"."&B22 -> 3.B.DSHNQN.STA.701 | B22: =TEXT(COUNTIFS($C$3:C22,C22,$D$3:D22,D22,$F$3:F22,F22)+IF(F22="KT",100,IF(F22="KC",200,IF(F22="DI",300,IF(F22="DN",400,IF(F22="NU",500,IF(F22="DH",600,IF(F22="PC",700,0))))))),"000") -> 701 | C22: Quản lý BIM | D22: B.DSHNQN.STA | E22: Nhà ga Cổ Loa | F22: PC | G22: KSCL mô hình BIM | H22: TKBVTC | I22: Cao | J22: Nguyễn Văn Hải | M22: 46170 | N22: 46230 | O22: =J22&", "&K22&", "&L22 -> Nguyễn Văn Hải, ,
A23: ="3."&D23&"."&B23 -> 3.B.DSHNQN.STA.102 | B23: =TEXT(COUNTIFS($C$3:C23,C23,$D$3:D23,D23,$F$3:F23,F23)+IF(F23="KT",100,IF(F23="KC",200,IF(F23="DI",300,IF(F23="DN",400,IF(F23="NU",500,IF(F23="DH",600,IF(F23="PC",700,0))))))),"000") -> 102 | C23: Quản lý BIM | D23: B.DSHNQN.STA | E23: Nhà ga Gia Bình | F23: KT | G23: Tạo lập mô hình BIM | H23: TKBVTC | I23: Cao | J23: Trần Văn Diện | M23: 46212 | N23: 46230 | O23: =J23&", "&K23&", "&L23 -> Trần Văn Diện, ,
... A28: ="3."&D28&"."&B28 -> 3.B.DSHNQN.STA.702 | B28: =TEXT(COUNTIFS($C$3:C28,C28,$D$3:D28,D28,$F$3:F28,F28)+IF(F28="KT",100,IF(F28="KC",200,IF(F28="DI",300,IF(F28="DN",400,IF(F28="NU",500,IF(F28="DH",600,IF(F28="PC",700,0))))))),"000") -> 702 | C28: Quản lý BIM | D28: B.DSHNQN.STA | E28: Nhà ga Gia Bình | F28: PC | G28: KSCL mô hình BIM | H28: TKBVTC | I28: Cao | J28: Nguyễn Văn Hải | M28: 46212 | N28: 46230 | O28: =J28&", "&K28&", "&L28 -> Nguyễn Văn Hải, ,
A29: ="3."&D29&"."&B29 -> 3.B.DSHNQN.STA.103 | B29: =TEXT(COUNTIFS($C$3:C29,C29,$D$3:D29,D29,$F$3:F29,F29)+IF(F29="KT",100,IF(F29="KC",200,IF(F29="DI",300,IF(F29="DN",400,IF(F29="NU",500,IF(F29="DH",600,IF(F29="PC",700,0))))))),"000") -> 103 | C29: Quản lý BIM | D29: B.DSHNQN.STA | E29: Nhà ga Hạ Long Xanh | F29: KT | G29: Tạo lập mô hình BIM | H29: TKBVTC | I29: Cao | J29: Trần Văn Toản | K29: Vũ Thị Thêu | M29: 46114 | N29: 46212 | O29: =J29&", "&K29&", "&L29 -> Trần Văn Toản, Vũ Thị Thêu,
A30: ="3."&D30&"."&B30 -> 3.B.DSHNQN.STA.201 | B30: =TEXT(COUNTIFS($C$3:C30,C30,$D$3:D30,D30,$F$3:F30,F30)+IF(F30="KT",100,IF(F30="KC",200,IF(F30="DI",300,IF(F30="DN",400,IF(F30="NU",500,IF(F30="DH",600,IF(F30="PC",700,0))))))),"000") -> 201 | C30: Quản lý BIM | D30: B.DSHNQN.STA | E30: Nhà ga Hạ Long Xanh | F30: KC | G30: KSCL mô hình BIM | H30: TKBVTC | I30: Cao | J30: Trần Văn Toản | K30: Vũ Thị Thêu | M30: 46154 | N30: 46330 | O30: =J30&", "&K30&", "&L30 -> Trần Văn Toản, Vũ Thị Thêu,
A31: ="3."&D31&"."&B31 -> 3.B.DSHNQN.STA.303 | B31: =TEXT(COUNTIFS($C$3:C31,C31,$D$3:D31,D31,$F$3:F31,F31)+IF(F31="KT",100,IF(F31="KC",200,IF(F31="DI",300,IF(F31="DN",400,IF(F31="NU",500,IF(F31="DH",600,IF(F31="PC",700,0))))))),"000") -> 303 | C31: Quản lý BIM | D31: B.DSHNQN.STA | E31: Nhà ga Hạ Long Xanh | F31: DI | G31: KSCL mô hình BIM | H31: TKBVTC | I31: Cao | J31: Nguyễn Văn Hải | M31: 46186 | N31: 46230 | O31: =J31&", "&K31&", "&L31 -> Nguyễn Văn Hải, ,
A32: ="3."&D32&"."&B32 -> 3.B.DSHNQN.STA.403 | B32: =TEXT(COUNTIFS($C$3:C32,C32,$D$3:D32,D32,$F$3:F32,F32)+IF(F32="KT",100,IF(F32="KC",200,IF(F32="DI",300,IF(F32="DN",400,IF(F32="NU",500,IF(F32="DH",600,IF(F32="PC",700,0))))))),"000") -> 403 | C32: Quản lý BIM | D32: B.DSHNQN.STA | E32: Nhà ga Hạ Long Xanh | F32: DN | G32: KSCL mô hình BIM | H32: TKBVTC | I32: Cao | J32: Nguyễn Văn Hải | M32: 46186 | N32: 46230 | O32: =J32&", "&K32&", "&L32 -> Nguyễn Văn Hải, ,
A33: ="3."&D33&"."&B33 -> 3.B.DSHNQN.STA.503 | B33: =TEXT(COUNTIFS($C$3:C33,C33,$D$3:D33,D33,$F$3:F33,F33)+IF(F33="KT",100,IF(F33="KC",200,IF(F33="DI",300,IF(F33="DN",400,IF(F33="NU",500,IF(F33="DH",600,IF(F33="PC",700,0))))))),"000") -> 503 | C33: Quản lý BIM | D33: B.DSHNQN.STA | E33: Nhà ga Hạ Long Xanh | F33: NU | G33: KSCL mô hình BIM | H33: TKBVTC | I33: Cao | J33: Nguyễn Văn Hải | M33: 46186 | N33: 46230 | O33: =J33&", "&K33&", "&L33 -> Nguyễn Văn Hải, ,
A34: ="3."&D34&"."&B34 -> 3.B.DSHNQN.STA.603 | B34: =TEXT(COUNTIFS($C$3:C34,C34,$D$3:D34,D34,$F$3:F34,F34)+IF(F34="KT",100,IF(F34="KC",200,IF(F34="DI",300,IF(F34="DN",400,IF(F34="NU",500,IF(F34="DH",600,IF(F34="PC",700,0))))))),"000") -> 603 | C34: Quản lý BIM | D34: B.DSHNQN.STA | E34: Nhà ga Hạ Long Xanh | F34: DH | G34: KSCL mô hình BIM | H34: TKBVTC | I34: Cao | J34: Nguyễn Văn Hải | M34: 46186 | N34: 46230 | O34: =J34&", "&K34&", "&L34 -> Nguyễn Văn Hải, ,
A35: ="3."&D35&"."&B35 -> 3.B.DSHNQN.STA.703 | B35: =TEXT(COUNTIFS($C$3:C35,C35,$D$3:D35,D35,$F$3:F35,F35)+IF(F35="KT",100,IF(F35="KC",200,IF(F35="DI",300,IF(F35="DN",400,IF(F35="NU",500,IF(F35="DH",600,IF(F35="PC",700,0))))))),"000") -> 703 | C35: Quản lý BIM | D35: B.DSHNQN.STA | E35: Nhà ga Hạ Long Xanh | F35: PC | G35: KSCL mô hình BIM | H35: TKBVTC | I35: Cao | J35: Nguyễn Văn Hải | M35: 46186 | N35: 46230 | O35: =J35&", "&K35&", "&L35 -> Nguyễn Văn Hải, ,
A36: ="3."&D36&"."&B36 -> 3.B.DSHNQN.STA.104 | B36: =TEXT(COUNTIFS($C$3:C36,C36,$D$3:D36,D36,$F$3:F36,F36)+IF(F36="KT",100,IF(F36="KC",200,IF(F36="DI",300,IF(F36="DN",400,IF(F36="NU",500,IF(F36="DH",600,IF(F36="PC",700,0))))))),"000") -> 104 | C36: Quản lý BIM | D36: B.DSHNQN.STA | E36: Nhà ga Ninh Xá | F36: KT | G36: Tạo lập mô hình BIM | H36: TKBVTC | I36: Cao | J36: Trần Văn Toản | K36: Vũ Thị Thêu | M36: 46128 | N36: 46206 | O36: =J36&", "&K36&", "&L36 -> Trần Văn Toản, Vũ Thị Thêu,
A37: ="3."&D37&"."&B37 -> 3.B.DSHNQN.STA.202 | B37: =TEXT(COUNTIFS($C$3:C37,C37,$D$3:D37,D37,$F$3:F37,F37)+IF(F37="KT",100,IF(F37="KC",200,IF(F37="DI",300,IF(F37="DN",400,IF(F37="NU",500,IF(F37="DH",600,IF(F37="PC",700,0))))))),"000") -> 202 | C37: Quản lý BIM | D37: B.DSHNQN.STA | E37: Nhà ga Ninh Xá | F37: KC | G37: KSCL mô hình BIM | H37: TKBVTC | I37: Cao | J37: Trần Văn Toản | K37: Vũ Thị Thêu | M37: 46163 | N37: 46330 | O37: =J37&", "&K37&", "&L37 -> Trần Văn Toản, Vũ Thị Thêu,
A38: ="3."&D38&"."&B38 -> 3.B.DSHNQN.STA.304 | B38: =TEXT(COUNTIFS($C$3:C38,C38,$D$3:D38,D38,$F$3:F38,F38)+IF(F38="KT",100,IF(F38="KC",200,IF(F38="DI",300,IF(F38="DN",400,IF(F38="NU",500,IF(F38="DH",600,IF(F38="PC",700,0))))))),"000") -> 304 | C38: Quản lý BIM | D38: B.DSHNQN.STA | E38: Nhà ga Ninh Xá | F38: DI | G38: KSCL mô hình BIM | H38: TKBVTC | I38: Cao | J38: Đặng Thái Sơn | M38: 46212 | N38: 46230 | O38: =J38&", "&K38&", "&L38 -> Đặng Thái Sơn, ,
A39: ="3."&D39&"."&B39 -> 3.B.DSHNQN.STA.404 | B39: =TEXT(COUNTIFS($C$3:C39,C39,$D$3:D39,D39,$F$3:F39,F39)+IF(F39="KT",100,IF(F39="KC",200,IF(F39="DI",300,IF(F39="DN",400,IF(F39="NU",500,IF(F39="DH",600,IF(F39="PC",700,0))))))),"000") -> 404 | C39: Quản lý BIM | D39: B.DSHNQN.STA | E39: Nhà ga Ninh Xá | F39: DN | G39: KSCL mô hình BIM | H39: TKBVTC | I39: Cao | J39: Đặng Thái Sơn | M39: 46212 | N39: 46230 | O39: =J39&", "&K39&", "&L39 -> Đặng Thái Sơn, ,
A40: ="3."&D40&"."&B40 -> 3.B.DSHNQN.STA.504 | B40: =TEXT(COUNTIFS($C$3:C40,C40,$D$3:D40,D40,$F$3:F40,F40)+IF(F40="KT",100,IF(F40="KC",200,IF(F40="DI",300,IF(F40="DN",400,IF(F40="NU",500,IF(F40="DH",600,IF(F40="PC",700,0))))))),"000") -> 504 | C40: Quản lý BIM | D40: B.DSHNQN.STA | E40: Nhà ga Ninh Xá | F40: NU | G40: KSCL mô hình BIM | H40: TKBVTC | I40: Cao | J40: Đặng Thái Sơn | M40: 46212 | N40: 46230 | O40: =J40&", "&K40&", "&L40 -> Đặng Thái Sơn, ,
A41: ="3."&D41&"."&B41 -> 3.B.DSHNQN.STA.604 | B41: =TEXT(COUNTIFS($C$3:C41,C41,$D$3:D41,D41,$F$3:F41,F41)+IF(F41="KT",100,IF(F41="KC",200,IF(F41="DI",300,IF(F41="DN",400,IF(F41="NU",500,IF(F41="DH",600,IF(F41="PC",700,0))))))),"000") -> 604 | C41: Quản lý BIM | D41: B.DSHNQN.STA | E41: Nhà ga Ninh Xá | F41: DH | G41: KSCL mô hình BIM | H41: TKBVTC | I41: Cao | J41: Đặng Thái Sơn | M41: 46212 | N41: 46230 | O41: =J41&", "&K41&", "&L41 -> Đặng Thái Sơn, ,
A42: ="3."&D42&"."&B42 -> 3.B.DSHNQN.STA.704 | B42: =TEXT(COUNTIFS($C$3:C42,C42,$D$3:D42,D42,$F$3:F42,F42)+IF(F42="KT",100,IF(F42="KC",200,IF(F42="DI",300,IF(F42="DN",400,IF(F42="NU",500,IF(F42="DH",600,IF(F42="PC",700,0))))))),"000") -> 704 | C42: Quản lý BIM | D42: B.DSHNQN.STA | E42: Nhà ga Ninh Xá | F42: PC | G42: KSCL mô hình BIM | H42: TKBVTC | I42: Cao | J42: Đặng Thái Sơn | M42: 46212 | N42: 46230 | O42: =J42&", "&K42&", "&L42 -> Đặng Thái Sơn, ,
A43: ="3."&D43&"."&B43 -> 3.B.DSHNQN.STA.105 | B43: =TEXT(COUNTIFS($C$3:C43,C43,$D$3:D43,D43,$F$3:F43,F43)+IF(F43="KT",100,IF(F43="KC",200,IF(F43="DI",300,IF(F43="DN",400,IF(F43="NU",500,IF(F43="DH",600,IF(F43="PC",700,0))))))),"000") -> 105 | C43: Quản lý BIM | D43: B.DSHNQN.STA | E43: Nhà ga Yên Tử | F43: KT | G43: Tạo lập mô hình BIM | H43: TKBVTC | I43: Cao | J43: Nguyễn Hải Nam | K43: Đỗ Minh Ngọc | M43: 46146 | N43: 46317 | O43: =J43&", "&K43&", "&L43 -> Nguyễn Hải Nam, Đỗ Minh Ngọc,
A44: ="3."&D44&"."&B44 -> 3.B.DSHNQN.STA.203 | B44: =TEXT(COUNTIFS($C$3:C44,C44,$D$3:D44,D44,$F$3:F44,F44)+IF(F44="KT",100,IF(F44="KC",200,IF(F44="DI",300,IF(F44="DN",400,IF(F44="NU",500,IF(F44="DH",600,IF(F44="PC",700,0))))))),"000") -> 203 | C44: Quản lý BIM | D44: B.DSHNQN.STA | E44: Nhà ga Yên Tử | F44: KC | G44: KSCL mô hình BIM | H44: TKBVTC | I44: Cao | J44: Nguyễn Hải Nam | K44: Đỗ Minh Ngọc | M44: 46162 | N44: 46317 | O44: =J44&", "&K44&", "&L44 -> Nguyễn Hải Nam, Đỗ Minh Ngọc,
...

Sheet Bảng 4
C1: BẢNG GIAO VIỆC THANH TRA BIM
A2: Sum ID | B2: Sub ID | C2: Level 1 | D2: Level 2 | E2: Level 3 | F2: Level 4 | G2: Level 5 | H2: Mức độ ưu tiên | I2: Nhân sự thực hiện 01 | J2: Nhân sự thực hiện 02 | K2: Nhân sự thực hiện 03 | L2: Bắt đầu | M2: Kết thúc
A3: ="4."&D3&"."&B3 -> 4.B.HNO.VHOHN.SVD.001 | B3: 001 | C3: Thanh tra BIM | D3: B.HNO.VHOHN.SVD | E3: Khách sạn lô B5.02.04 | F3: BIM | G3: Đánh giá KSCL mô hình | H3: Cao
A4: ="4."&D4&"."&B4 -> 4.B.HYE.PVF.002 | B4: 002 | C4: Thanh tra BIM | D4: B.HYE.PVF | G4: Lấy ý kiến xác nhận lỗi | H4: Cao
A5: ="4."&D5&"."&B5 -> 4..003 | B5: 003 | C5: Thanh tra BIM | G5: Lập BB XLVP | H5: Cao
A6: ="4."&D6&"."&B6 -> 4..004 | B6: 004 | C6: Thanh tra BIM | H6: Cao
A7: ="4."&D7&"."&B7 -> 4..005 | B7: 005 | C7: Thanh tra BIM | H7: Cao
A8: ="4."&D8&"."&B8 -> 4..006 | B8: 006 | C8: Thanh tra BIM | H8: Cao
A9: ="4."&D9&"."&B9 -> 4..007 | B9: 007 | C9: Thanh tra BIM | H9: Cao
A10: ="4."&D10&"."&B10 -> 4..008 | B10: 008 | C10: Thanh tra BIM | H10: Cao
A11: ="4."&D11&"."&B11 -> 4..009 | B11: 009 | C11: Thanh tra BIM | H11: Cao
A12: ="4."&D12&"."&B12 -> 4..010 | B12: 010 | C12: Thanh tra BIM | H12: Cao
A13: ="4."&D13&"."&B13 -> 4..011 | B13: 011 | C13: Thanh tra BIM | H13: Cao
A14: ="4."&D14&"."&B14 -> 4..012 | B14: 012 | C14: Thanh tra BIM | H14: Cao
A15: ="4."&D15&"."&B15 -> 4..013 | B15: 013 | C15: Thanh tra BIM | H15: Cao
A16: ="4."&D16&"."&B16 -> 4..014 | B16: 014 | C16: Thanh tra BIM | H16: Cao
A17: ="4."&D17&"."&B17 -> 4..015 | B17: 015 | C17: Thanh tra BIM | H17: Cao

Sheet Bảng 5
C1: BẢNG GIAO VIỆC PHÁT TRIỂN BIM TOOLS
A2: Sum ID | B2: Sub ID | C2: Level 1 | D2: Level 2 | E2: Level 3 | F2: Level 4 | G2: Level 5 | H2: Mức độ ưu tiên | I2: Nhân sự thực hiện 01 | J2: Nhân sự thực hiện 02 | K2: Nhân sự thực hiện 03 | L2: Bắt đầu | M2: Kết thúc
A3: ="5."&D3&"."&B3 -> 5.Revit.01 | B3: 01 | C3: Phát triển BIM Tools | D3: Revit | E3: Dàn trang tài liệu bán hàng CAD | F3: BIM IT | G3: Thực hiện Code | H3: Cao | I3: Nguyễn Thanh Phương | L3: 46177 | M3: 46177
A4: ="5."&D4&"."&B4 -> 5.Revit.02 | B4: 02 | C4: Phát triển BIM Tools | D4: Revit | E4: Dàn trang tài liệu bán hàng CAD | F4: BIM IT | G4: Chạy thử và Đánh giá | H4: Cao | I4: Nguyễn Thanh Phương | L4: 46177 | M4: 46177
A5: ="5."&D5&"."&B5 -> 5.Revit.03 | B5: 03 | C5: Phát triển BIM Tools | D5: Revit | E5: Dàn trang tài liệu bán hàng CAD | F5: BIM IT | G5: Hướng dẫn sử dụng | H5: Cao | I5: Nguyễn Thanh Phương | L5: 46177 | M5: 46177
A6: ="5."&D6&"."&B6 -> 5.Revit.04 | B6: 04 | C6: Phát triển BIM Tools | D6: Revit | E6: Dàn trang tài liệu bán hàng CAD | F6: BIM IT | G6: Xuất bản | H6: Cao | I6: Nguyễn Thanh Phương | L6: 46177 | M6: 46177
A7: ="5."&D7&"."&B7 -> 5.Revit.05 | B7: 05 | C7: Phát triển BIM Tools | D7: Revit | E7: Edit Tường, Sàn KT | F7: BIM IT | G7: Ghi nhận yêu cầu và tìm hiểu nghiệp vụ | H7: Trung bình | I7: Nguyễn Thanh Phương | L7: 46161 | M7: 46161
A8: ="5."&D8&"."&B8 -> 5.Revit.06 | B8: 06 | C8: Phát triển BIM Tools | D8: Revit | E8: Edit Tường, Sàn KT | F8: BIM IT | G8: Lên và Trình PD phương án | H8: Trung bình | I8: Nguyễn Thanh Phương
A9: ="5."&D9&"."&B9 -> 5.Revit.07 | B9: 07 | C9: Phát triển BIM Tools | D9: Revit | E9: Edit Tường, Sàn KT | F9: BIM IT | G9: Thực hiện Code | H9: Trung bình | I9: Nguyễn Thanh Phương | L9: 46162 | M9: 46174
A10: ="5."&D10&"."&B10 -> 5.Revit.08 | B10: 08 | C10: Phát triển BIM Tools | D10: Revit | E10: Edit Tường, Sàn KT | F10: BIM IT | G10: Chạy thử và Đánh giá | H10: Trung bình | I10: Nguyễn Thanh Phương | L10: 46174 | M10: 46174
A11: ="5."&D11&"."&B11 -> 5.Revit.09 | B11: 09 | C11: Phát triển BIM Tools | D11: Revit | E11: Edit Tường, Sàn KT | F11: BIM IT | G11: Fix lỗi | H11: Trung bình | I11: Nguyễn Thanh Phương
A12: ="5."&D12&"."&B12 -> 5.Revit.10 | B12: 10 | C12: Phát triển BIM Tools | D12: Revit | E12: Edit Tường, Sàn KT | F12: BIM IT | G12: Hướng dẫn sử dụng | H12: Trung bình | I12: Nguyễn Thanh Phương | L12: 46175 | M12: 46175
A13: ="5."&D13&"."&B13 -> 5.Revit.11 | B13: 11 | C13: Phát triển BIM Tools | D13: Revit | E13: Edit Tường, Sàn KT | F13: BIM IT | G13: Xuất bản | H13: Trung bình | I13: Nguyễn Thanh Phương | L13: 46176 | M13: 46176
A14: ="5."&D14&"."&B14 -> 5.Revit.12 | B14: 12 | C14: Phát triển BIM Tools | D14: Revit | E14: Thống kê tình trạng bàn giao đất | F14: BIM IT | G14: Ghi nhận yêu cầu và tìm hiểu nghiệp vụ | H14: Cao | I14: Nguyễn Thanh Phương | L14: 46157 | M14: 46157
A15: ="5."&D15&"."&B15 -> 5.Revit.13 | B15: 13 | C15: Phát triển BIM Tools | D15: Revit | E15: Thống kê tình trạng bàn giao đất | F15: BIM IT | G15: Lên và Trình PD phương án | H15: Cao | I15: Nguyễn Thanh Phương
A16: ="5."&D16&"."&B16 -> 5.Revit.14 | B16: 14 | C16: Phát triển BIM Tools | D16: Revit | E16: Thống kê tình trạng bàn giao đất | F16: BIM IT | G16: Thực hiện Code | H16: Cao | I16: Nguyễn Thanh Phương | L16: 46157 | M16: 46160
A17: ="5."&D17&"."&B17 -> 5.Revit.15 | B17: 15 | C17: Phát triển BIM Tools | D17: Revit | E17: Thống kê tình trạng bàn giao đất | F17: BIM IT | G17: Chạy thử và Đánh giá | H17: Cao | I17: Nguyễn Thanh Phương
A18: ="5."&D18&"."&B18 -> 5.Revit.16 | B18: 16 | C18: Phát triển BIM Tools | D18: Revit | E18: Thống kê tình trạng bàn giao đất | F18: BIM IT | G18: Fix lỗi | H18: Cao | I18: Nguyễn Thanh Phương
A19: ="5."&D19&"."&B19 -> 5.Revit.17 | B19: 17 | C19: Phát triển BIM Tools | D19: Revit | E19: Thống kê tình trạng bàn giao đất | F19: BIM IT | G19: Hướng dẫn sử dụng | H19: Cao | I19: Nguyễn Thanh Phương | L19: 46175 | M19: 46175
A20: ="5."&D20&"."&B20 -> 5.Revit.18 | B20: 18 | C20: Phát triển BIM Tools | D20: Revit | E20: Thống kê tình trạng bàn giao đất | F20: BIM IT | G20: Xuất bản | H20: Cao | I20: Nguyễn Thanh Phương | L20: 46176 | M20: 46176
A21: ="5."&D21&"."&B21 -> 5.Revit.19 | B21: 19 | C21: Phát triển BIM Tools | D21: Revit | E21: QC mô hình | F21: BIM IT | G21: Ghi nhận yêu cầu và tìm hiểu nghiệp vụ | H21: Cao | I21: Nguyễn Thanh Phương | L21: 46165 | M21: 46165
A22: ="5."&D22&"."&B22 -> 5.Revit.20 | B22: 20 | C22: Phát triển BIM Tools | D22: Revit | E22: QC mô hình | F22: BIM IT | G22: Lên và Trình PD phương án | H22: Cao | I22: Nguyễn Thanh Phương
A23: ="5."&D23&"."&B23 -> 5.Revit.21 | B23: 21 | C23: Phát triển BIM Tools | D23: Revit | E23: QC mô hình | F23: BIM IT | G23: Thực hiện Code | H23: Cao | I23: Nguyễn Thanh Phương
A24: ="5."&D24&"."&B24 -> 5.Revit.22 | B24: 22 | C24: Phát triển BIM Tools | D24: Revit | E24: QC mô hình | F24: BIM IT | G24: Chạy thử và Đánh giá | H24: Cao | I24: Nguyễn Thanh Phương | L24: 46175 | M24: 46175
A25: ="5."&D25&"."&B25 -> 5.Revit.23 | B25: 23 | C25: Phát triển BIM Tools | D25: Revit | E25: QC mô hình | F25: BIM IT | G25: Hướng dẫn sử dụng | H25: Cao | I25: Nguyễn Thanh Phương | L25: 46175 | M25: 46175
A26: ="5."&D26&"."&B26 -> 5.Revit.24 | B26: 24 | C26: Phát triển BIM Tools | D26: Revit | E26: QC mô hình | F26: BIM IT | G26: Xuất bản | H26: Cao | I26: Nguyễn Thanh Phương | L26: 46176 | M26: 46176
A27: ="5."&D27&"."&B27 -> 5.Web App.25 | B27: 25 | C27: Phát triển BIM Tools | D27: Web App | E27: KSCL và Điều phối | F27: BIM IT | G27: Xuất bản | H27: Cao | I27: Nguyễn Thanh Phương | L27: 46176 | M27: 46203
A28: ="5."&D28&"."&B28 -> 5.Revit.26 | B28: 26 | C28: Phát triển BIM Tools | D28: Revit | E28: Cắt bê tông | F28: BIM IT | G28: Ghi nhận yêu cầu và tìm hiểu nghiệp vụ | H28: Trung bình | I28: Lê Huy Toàn | L28: 46162 | M28: 46162
A29: ="5."&D29&"."&B29 -> 5.Revit.27 | B29: 27 | C29: Phát triển BIM Tools | D29: Revit | E29: Cắt bê tông | F29: BIM IT | G29: Lên và Trình PD phương án | H29: Trung bình | I29: Lê Huy Toàn | L29: 46162 | M29: 46162
A30: ="5."&D30&"."&B30 -> 5.Revit.28 | B30: 28 | C30: Phát triển BIM Tools | D30: Revit | E30: Cắt bê tông | F30: BIM IT | G30: Thực hiện Code | H30: Trung bình | I30: Lê Huy Toàn | L30: 46163 | M30: 46174
A31: ="5."&D31&"."&B31 -> 5.Revit.29 | B31: 29 | C31: Phát triển BIM Tools | D31: Revit | E31: Cắt bê tông | F31: BIM IT | G31: Chạy thử và Đánh giá | H31: Trung bình | I31: Lê Huy Toàn | L31: 46174 | M31: 46175
A32: ="5."&D32&"."&B32 -> 5.Revit.30 | B32: 30 | C32: Phát triển BIM Tools | D32: Revit | E32: Cắt bê tông | F32: BIM IT | G32: Fix lỗi | H32: Trung bình | I32: Lê Huy Toàn | L32: 46175 | M32: 46175
A33: ="5."&D33&"."&B33 -> 5.Revit.31 | B33: 31 | C33: Phát triển BIM Tools | D33: Revit | E33: Cắt bê tông | F33: BIM IT | G33: Hướng dẫn sử dụng | H33: Trung bình | I33: Lê Huy Toàn | L33: 46175 | M33: 46175
A34: ="5."&D34&"."&B34 -> 5.Revit.32 | B34: 32 | C34: Phát triển BIM Tools | D34: Revit | E34: Cắt bê tông | F34: BIM IT | G34: Xuất bản | H34: Trung bình | I34: Lê Huy Toàn | L34: 46175 | M34: 46175
A35: ="5."&D35&"."&B35 -> 5.CAD.33 | B35: 33 | C35: Phát triển BIM Tools | D35: CAD | E35: Ghép dãy thấp tầng | F35: BIM IT | G35: Ghi nhận yêu cầu và tìm hiểu nghiệp vụ | H35: Cao | I35: Lê Huy Toàn | L35: 46168 | M35: 46168
... A48: ="5."&D48&"."&B48 -> 5.Didital Twin.46 | B48: 46 | C48: Phát triển BIM Tools | D48: Didital Twin | E48: App Digital Twin V1 | F48: BIM IT | G48: Xuất bản | H48: Cao | I48: Lê Huy Toàn | L48: 46213 | M48: 46214
A49: 5.Didital Twin.138 | B49: 47 | C49: Phát triển BIM Tools | D49: Didital Twin | E49: App Digital Twin V2 | F49: BIM IT | G49: Ghi nhận yêu cầu và tìm hiểu nghiệp vụ | H49: Cao | I49: Lê Huy Toàn | L49: 46216 | M49: 46218
A50: 5.Didital Twin.139 | B50: 48 | C50: Phát triển BIM Tools | D50: Didital Twin | E50: App Digital Twin V2 | F50: BIM IT | G50: Lên và Trình PD phương án | H50: Cao | I50: Lê Huy Toàn | L50: 46219 | M50: 46221
A51: 5.Didital Twin.140 | B51: 49 | C51: Phát triển BIM Tools | D51: Didital Twin | E51: App Digital Twin V2 | F51: BIM IT | G51: Thực hiện Code | H51: Cao | I51: Lê Huy Toàn | L51: 46223 | M51: 46244
A52: 5.Didital Twin.141 | B52: 50 | C52: Phát triển BIM Tools | D52: Didital Twin | E52: App Digital Twin V2 | F52: BIM IT | G52: Chạy thử và Đánh giá | H52: Cao | I52: Lê Huy Toàn | L52: 46245 | M52: 46247
...

Sheet Bảng 6
C1: BẢNG GIAO VIỆC QUẢN LÝ PHẦN MỀM
A2: Sum ID | B2: Sub ID | C2: Level 1 | D2: Level 2 | E2: Level 3 | F2: Level 4 | G2: Level 5 | H2: Mức độ ưu tiên | I2: Nhân sự thực hiện | J2: Bắt đầu | K2: Kết thúc | L2: Hoàn thành thực tế | M2: Tổng số ngày | N2: Tổng số giờ
A3: ="6."&D3&"."&B3 -> 6.DuAn.LoaiHinh.001 | B3: 001 | C3: Quản lý phần mềm | D3: DuAn.LoaiHinh | E3: Hạng mục 1 | F3: BIM IT | G3: Khảo sát nhu cầu và cân đối số lượng | H3: Cao | I3: Nguyễn Văn Tuyên
A4: ="6."&D4&"."&B4 -> 6..002 | B4: 002 | C4: Quản lý phần mềm | E4: Hạng mục 2 | F4: BIM IT | H4: Trung bình | I4: Nguyễn Văn Tuyên
A5: ="6."&D5&"."&B5 -> 6..003 | B5: 003 | C5: Quản lý phần mềm | E5: Hạng mục 3 | F5: BIM IT | H5: Thấp | I5: Nguyễn Văn Tuyên
A6: ="6."&D6&"."&B6 -> 6..004 | B6: 004 | C6: Quản lý phần mềm | E6: Hạng mục 4 | F6: BIM IT | I6: Nguyễn Văn Tuyên
A7: ="6."&D7&"."&B7 -> 6..005 | B7: 005 | C7: Quản lý phần mềm | E7: Hạng mục 5 | F7: BIM IT | I7: Nguyễn Văn Tuyên
A8: ="6."&D8&"."&B8 -> 6..006 | B8: 006 | C8: Quản lý phần mềm | E8: Hạng mục 6 | F8: BIM IT | I8: Nguyễn Văn Tuyên
A9: ="6."&D9&"."&B9 -> 6..007 | B9: 007 | C9: Quản lý phần mềm | E9: Hạng mục 7 | F9: BIM IT | I9: Nguyễn Văn Tuyên
A10: ="6."&D10&"."&B10 -> 6..008 | B10: 008 | C10: Quản lý phần mềm | E10: Hạng mục 8 | F10: BIM IT | I10: Nguyễn Văn Tuyên
A11: ="6."&D11&"."&B11 -> 6..009 | B11: 009 | C11: Quản lý phần mềm | E11: Hạng mục 9 | F11: BIM IT | I11: Nguyễn Văn Tuyên
A12: ="6."&D12&"."&B12 -> 6..010 | B12: 010 | C12: Quản lý phần mềm | E12: Hạng mục 10 | F12: BIM IT | I12: Nguyễn Văn Tuyên
A13: ="6."&D13&"."&B13 -> 6..011 | B13: 011 | C13: Quản lý phần mềm | E13: Hạng mục 11 | F13: BIM IT | I13: Nguyễn Văn Tuyên
A14: ="6."&D14&"."&B14 -> 6..012 | B14: 012 | C14: Quản lý phần mềm | E14: Hạng mục 12 | F14: BIM IT | I14: Nguyễn Văn Tuyên
A15: ="6."&D15&"."&B15 -> 6..013 | B15: 013 | C15: Quản lý phần mềm | E15: Hạng mục 13 | F15: BIM IT | I15: Nguyễn Văn Tuyên
A16: ="6."&D16&"."&B16 -> 6..014 | B16: 014 | C16: Quản lý phần mềm | E16: Hạng mục 14 | F16: BIM IT | I16: Nguyễn Văn Tuyên
A17: ="6."&D17&"."&B17 -> 6..015 | B17: 015 | C17: Quản lý phần mềm | E17: Hạng mục 15 | F17: BIM IT | I17: Nguyễn Văn Tuyên

Sheet Draft
A1: TỔNG QUAN CÁC CÔNG VIỆC PHÒNG BIM
A2: Trình tự | B2: Công việc chính | C2: Chi tiết | D2: Ghi chú | E2: Trách nhiệm
A3: Bước 1 | B3: Xây dựng HTTC BIM | C3: Quy định triển khai BIM | D3: Đã bao gồm các phụ lục và biểu mẫu | E3: All
C4: Quy định thanh tra BIM
A5: Bước 2 | B5: Đào tạo BIM | C5: HTTC BIM | E5: All
C6: CDE
C7: Công cụ tạo lập mô hình
C8: Công cụ quản lý mô hình
C9: BIM Tools
A10: Bước 3 | B10: Quản lý BIM | C10: Set up hệ thống DR3 | D10: Áp vào các dự án VTK đang thực hiện | E10: Anh Tuyên
C11: KSCL DR3 | E11: All
C12: Set up hệ thống CDE | E12: Anh Tuyên
C13: KSCL CDE | E13: All
C14: Điều phối CDE | E14: BIM XD, MEP, HT
C15: Khởi tạo mô hình BIM | E15: BIM XD, MEP, HT
C16: Tạo lập mô hình BIM | E16: BIM XD, MEP, HT
C17: Tạo lập thư viện | E17: BIM XD, MEP, HT
C18: KSCL mô hình BIM | E18: BIM XD, MEP, HT
C19: Điều phối BIM | E19: BIM XD, MEP, HT
C20: Tổng hợp số liệu QH | E20: BIM XD + IT
C21: Tổng hợp số liệu TT | E21: BIM XD + IT
C22: Triển khai hồ sơ thiết kế | E22: BIM XD, MEP, HT
... C24: Xuất khối lượng từ mô hình BIM | E24: BIM XD, MEP, HT
A25: Bước 4 | B25: Thực hiện thanh tra | E25: All
A26: Bước 5 | B26: Phát triển BIM Tools | C26: Tool tạo lập mô hình | E26: BIM IT
C27: Tool KSCL và Điều phối mô hình
C28: Tool khai thác thông tin mô hình
C29: Ứng dụng Digital Twin
A30: Bước 6 | B30: Quản lý phần mềm | C30: Khảo sát nhu cầu và cân đối số lượng | D30: Chung cho các PM | E30: GĐ + Chủ trì BIM
C31: Lập ngân sách trang bị PM
C32: Trình PD chủ trương trang bị PM
C33: Thẩm định giá và bổ nhiệm NCC | D33: Quản lý chi tiết đến từng PM | E33: VSF
C34: Lập PR-PO | E34: Anh Tuyên
C35: Ký kết HĐ
C36: BB nghiệm thu
C37: Thanh toán cho NCC
C38: Phân phối License

Sheet Bảng 7
C1: BẢNG GIAO VIỆC KHÁC
A2: Sum ID | B2: Sub ID | C2: Level 1 | D2: Level 2 | E2: Level 3 | F2: Level 4 | G2: Level 5 | H2: Mức độ ưu tiên | I2: Nhân sự thực hiện 01 | J2: Nhân sự thực hiện 02 | K2: Nhân sự thực hiện 03 | L2: Bắt đầu | M2: Kết thúc | N2: Hoàn thành thực tế | O2: Tổng số ngày | P2: Tổng số giờ
A3: ="1."&D3&"."&B3 -> 1.Công việc khác.001 | B3: 001 | C3: Công việc khác | D3: Công việc khác | E3: Công việc khác | F3: BIM | G3: Họp nội bộ | H3: Trung bình | I3: All
A4: ="1."&D4&"."&B4 -> 1.Công việc khác.002 | B4: 002 | C4: Công việc khác | D4: Công việc khác | E4: Công việc khác | F4: BIM | G4: Setup hệ thống quản lý công việc | H4: Cao | I4: All

Sheet XD
A1: BÁO CÁO CÔNG VIỆC HÀNG NGÀY - BIM.XD
A2: Nhân sự | B2: ID | C2: Level 1 | D2: Level 2 | E2: Level 3 | F2: Level 4 | G2: Level 5 | H2: Thực tế hoàn thành | I2: Tuần 21 | J2: Ngày | K2: Nội dung công việc | L2: Thời gian (h) | M2: Ngày | N2: Nội dung công việc | O2: Thời gian (h) | P2: Ngày | Q2: Nội dung công việc | R2: Thời gian (h) | S2: Ngày | T2: Nội dung công việc | U2: Thời gian (h) | V2: Ngày | W2: Nội dung công việc | X2: Thời gian (h) | Y2: Ngày | Z2: Nội dung công việc | AA2: Thời gian (h) | AB2: Tuần 22 | AC2: Ngày | AD2: Nội dung công việc | AE2: Thời gian (h) | AF2: Ngày | AG2: Nội dung công việc | AH2: Thời gian (h) | AI2: Ngày | AJ2: Nội dung công việc | AK2: Thời gian (h) | AL2: Ngày | AM2: Nội dung công việc | AN2: Thời gian (h) | AO2: Ngày | AP2: Nội dung công việc | AQ2: Thời gian (h) | AR2: Ngày | AS2: Nội dung công việc | AT2: Thời gian (h) | AU2: Tuần 23 | AV2: Ngày | AW2: Nội dung công việc | AX2: Thời gian (h) | AY2: Ngày | AZ2: Nội dung công việc | BA2: Thời gian (h) | BB2: Ngày | BC2: Nội dung công việc | BD2: Thời gian (h) | BE2: Ngày | BF2: Nội dung công việc | BG2: Thời gian (h) | BH2: Ngày | BI2: Nội dung công việc | BJ2: Thời gian (h) | BK2: Ngày | BL2: Nội dung công việc | BM2: Thời gian (h) | BN2: Tuần 24 | BO2: Ngày | BP2: Nội dung công việc | BQ2: Thời gian (h) | BR2: Ngày | BS2: Nội dung công việc | BT2: Thời gian (h) | BU2: Ngày | BV2: Nội dung công việc | BW2: Thời gian (h) | BX2: Ngày | BY2: Nội dung công việc | BZ2: Thời gian (h) | CA2: Ngày | CB2: Nội dung công việc | CC2: Thời gian (h) | CD2: Ngày | CE2: Nội dung công việc | CF2: Thời gian (h) | CG2: Tuần 25 | CH2: Ngày | CI2: Nội dung công việc | CJ2: Thời gian (h) | CK2: Ngày | CL2: Nội dung công việc | CM2: Thời gian (h) | CN2: Ngày | CO2: Nội dung công việc | CP2: Thời gian (h) | CQ2: Ngày | CR2: Nội dung công việc | CS2: Thời gian (h) | CT2: Ngày | CU2: Nội dung công việc | CV2: Thời gian (h) | CW2: Ngày | CX2: Nội dung công việc | CY2: Thời gian (h) | CZ2: Tuần 26 | DA2: Ngày | DB2: Nội dung công việc | DC2: Thời gian (h) | DD2: Ngày | DE2: Nội dung công việc | DF2: Thời gian (h) | DG2: Ngày | DH2: Nội dung công việc | DI2: Thời gian (h) | DJ2: Ngày | DK2: Nội dung công việc | DL2: Thời gian (h) | DM2: Ngày | DN2: Nội dung công việc | DO2: Thời gian (h) | DP2: Ngày | DQ2: Nội dung công việc | DR2: Thời gian (h)
J3: 46174 | M3: =J3+1 -> 46175 | P3: =J3+2 -> 46176 | S3: =J3+3 -> 46177 | V3: =J3+4 -> 46178 | Y3: =J3+5 -> 46179 | AC3: 46181 | AF3: =AC3+1 -> 46182 | AI3: =AC3+2 -> 46183 | AL3: =AC3+3 -> 46184 | AO3: =AC3+4 -> 46185 | AR3: =AC3+5 -> 46186 | AV3: 46188 | AY3: =AV3+1 -> 46189 | BB3: =AV3+2 -> 46190 | BE3: =AV3+3 -> 46191 | BH3: =AV3+4 -> 46192 | BK3: =AV3+5 -> 46193 | BO3: 46195 | BR3: =BO3+1 -> 46196 | BU3: =BO3+2 -> 46197 | BX3: =BO3+3 -> 46198 | CA3: =BO3+4 -> 46199 | CD3: =BO3+5 -> 46200 | CH3: 46202 | CK3: =CH3+1 -> 46203 | CN3: =CH3+2 -> 46204 | CQ3: =CH3+3 -> 46205 | CT3: =CH3+4 -> 46206 | CW3: =CH3+5 -> 46207 | DA3: 46209 | DD3: =DA3+1 -> 46210 | DG3: =DA3+2 -> 46211 | DJ3: =DA3+3 -> 46212 | DM3: =DA3+4 -> 46213 | DP3: =DA3+5 -> 46214
A4: Lý Huy Thành | C4: =IF($B4="","",INDEX('Bảng 3'!C:C,MATCH($B4,'Bảng 3'!$A:$A,0))) | D4: =IF($B4="","",INDEX('Bảng 3'!D:D,MATCH($B4,'Bảng 3'!$A:$A,0))) | E4: =IF($B4="","",INDEX('Bảng 3'!E:E,MATCH($B4,'Bảng 3'!$A:$A,0))) | F4: =IF($B4="","",INDEX('Bảng 3'!F:F,MATCH($B4,'Bảng 3'!$A:$A,0))) | G4: =IF($B4="","",INDEX('Bảng 3'!G:G,MATCH($B4,'Bảng 3'!$A:$A,0))) | J4: =J$3 -> 46174 | L4: =SUM(L5:L15) -> 10.25 | M4: =M$3 -> 46175 | O4: =SUM(O5:O15) -> 8.5 | P4: =P$3 -> 46176 | R4: =SUM(R5:R15) -> 0 | S4: =S$3 -> 46177 | U4: =SUM(U5:U15) -> 0 | V4: =V$3 -> 46178 | X4: =SUM(X5:X15) -> 0 | Y4: =Y$3 -> 46179 | AA4: =SUM(AA5:AA15) -> 0 | AC4: =AC$3 -> 46181 | AE4: =SUM(AE5:AE15) -> 0 | AF4: =AF$3 -> 46182 | AH4: =SUM(AH5:AH15) -> 0 | AI4: =AI$3 -> 46183 | AK4: =SUM(AK5:AK15) -> 0 | AL4: =AL$3 -> 46184 | AN4: =SUM(AN5:AN15) -> 0 | AO4: =AO$3 -> 46185 | AQ4: =SUM(AQ5:AQ15) -> 0 | AR4: =AR$3 -> 46186 | AT4: =SUM(AT5:AT15) -> 0 | AV4: =AV$3 -> 46188 | AX4: =SUM(AX5:AX15) -> 0 | AY4: =AY$3 -> 46189 | BA4: =SUM(BA5:BA15) -> 0 | BB4: =BB$3 -> 46190 | BD4: =SUM(BD5:BD15) -> 0 | BE4: =BE$3 -> 46191 | BG4: =SUM(BG5:BG15) -> 0 | BH4: =BH$3 -> 46192 | BJ4: =SUM(BJ5:BJ15) -> 0 | BK4: =BK$3 -> 46193 | BM4: =SUM(BM5:BM15) -> 0 | BO4: =BO$3 -> 46195 | BQ4: =SUM(BQ5:BQ15) -> 0 | BR4: =BR$3 -> 46196 | BT4: =SUM(BT5:BT15) -> 0 | BU4: =BU$3 -> 46197 | BW4: =SUM(BW5:BW15) -> 0 | BX4: =BX$3 -> 46198 | BZ4: =SUM(BZ5:BZ15) -> 0 | CA4: =CA$3 -> 46199 | CC4: =SUM(CC5:CC15) -> 0 | CD4: =CD$3 -> 46200 | CF4: =SUM(CF5:CF15) -> 0 | CH4: =CH$3 -> 46202 | CJ4: =SUM(CJ5:CJ15) -> 0 | CK4: =CK$3 -> 46203 | CM4: =SUM(CM5:CM15) -> 0 | CN4: =CN$3 -> 46204 | CP4: =SUM(CP5:CP15) -> 0 | CQ4: =CQ$3 -> 46205 | CS4: =SUM(CS5:CS15) -> 0 | CT4: =CT$3 -> 46206 | CV4: =SUM(CV5:CV15) -> 0 | CW4: =CW$3 -> 46207 | CY4: =SUM(CY5:CY15) -> 0 | DA4: =DA$3 -> 46209 | DC4: =SUM(DC5:DC15) -> 0 | DD4: =DD$3 -> 46210 | DF4: =SUM(DF5:DF15) -> 0 | DG4: =DG$3 -> 46211 | DI4: =SUM(DI5:DI15) -> 0 | DJ4: =DJ$3 -> 46212 | DL4: =SUM(DL5:DL15) -> 0 | DM4: =DM$3 -> 46213 | DO4: =SUM(DO5:DO15) -> 0 | DP4: =DP$3 -> 46214 | DR4: =SUM(DR5:DR15) -> 0
A5: =$A$4 -> Lý Huy Thành | B5: ='Bảng 3'!A335 -> 3.N.HCM.Q9.VP.101 | C5: =IF($B5="","",INDEX('Bảng 3'!C:C,MATCH($B5,'Bảng 3'!$A:$A,0))) -> Quản lý BIM | D5: =IF($B5="","",INDEX('Bảng 3'!D:D,MATCH($B5,'Bảng 3'!$A:$A,0))) -> N.HCM.Q9.VP | E5: =IF($B5="","",INDEX('Bảng 3'!E:E,MATCH($B5,'Bảng 3'!$A:$A,0))) -> Toà văn phòng 43 tầng | F5: =IF($B5="","",INDEX('Bảng 3'!F:F,MATCH($B5,'Bảng 3'!$A:$A,0))) -> KT | G5: =IF($B5="","",INDEX('Bảng 3'!G:G,MATCH($B5,'Bảng 3'!$A:$A,0))) -> Xuất khối lượng từ mô hình BIM | H5: 46174 | J5: =J$3 -> 46174 | K5: Xuất khối lượng Xây, trát, ốp lát. | L5: 1 | M5: =M$3 -> 46175 | P5: =P$3 -> 46176 | S5: =S$3 -> 46177 | V5: =V$3 -> 46178 | Y5: =Y$3 -> 46179 | AC5: =AC$3 -> 46181 | AF5: =AF$3 -> 46182 | AI5: =AI$3 -> 46183 | AL5: =AL$3 -> 46184 | AO5: =AO$3 -> 46185 | AR5: =AR$3 -> 46186 | AV5: =AV$3 -> 46188 | AY5: =AY$3 -> 46189 | BB5: =BB$3 -> 46190 | BE5: =BE$3 -> 46191 | BH5: =BH$3 -> 46192 | BK5: =BK$3 -> 46193 | BO5: =BO$3 -> 46195 | BR5: =BR$3 -> 46196 | BU5: =BU$3 -> 46197 | BX5: =BX$3 -> 46198 | CA5: =CA$3 -> 46199 | CD5: =CD$3 -> 46200 | CH5: =CH$3 -> 46202 | CK5: =CK$3 -> 46203 | CN5: =CN$3 -> 46204 | CQ5: =CQ$3 -> 46205 | CT5: =CT$3 -> 46206 | CW5: =CW$3 -> 46207 | DA5: =DA$3 -> 46209 | DD5: =DD$3 -> 46210 | DG5: =DG$3 -> 46211 | DJ5: =DJ$3 -> 46212 | DM5: =DM$3 -> 46213 | DP5: =DP$3 -> 46214
